<?xml version="1.0" ?>
<!-- =================================================================================== -->
<!-- |    This document was autogenerated by xacro from xMatePro7.xacro                | -->
<!-- |    EDITING THIS FILE BY HAND IS NOT RECOMMENDED                                 | -->
<!-- =================================================================================== -->
<!-- xMatePro7 manipulator -->
<!--  Attention!!! inertia in the model is not correct!!! -->
<robot name="erp7_model" xmlns:xacro="http://www.ros.org/wiki/xacro">
  <!-- Constants for robot dimensions -->
  <material name="black">
    <color rgba="0.0 0.0 0.0 1.0"/>
  </material>
  <material name="blue">
    <color rgba="0.0 0.0 0.8 1.0"/>
  </material>
  <material name="green">
    <color rgba="0.0 0.8 0.0 1.0"/>
  </material>
  <material name="grey">
    <color rgba="0.2 0.2 0.2 1.0"/>
  </material>
  <material name="orange">
    <color rgba="1.0 0.423529411765 0.0392156862745 1.0"/>
  </material>
  <material name="brown">
    <color rgba="0.870588235294 0.811764705882 0.764705882353 1.0"/>
  </material>
  <material name="red">
    <color rgba="0.8 0.0 0.0 1.0"/>
  </material>
  <material name="white">
    <color rgba="1.0 1.0 1.0 1.0"/>
  </material>
  <material name="Beige">
    <color rgba="1.0 0.784 0.5765 1.0"/>
  </material>
  <!-- Used for fixing robot to Gazebo 'base_link' -->
  <link name="world"/>
  <joint name="fixed" type="fixed">
    <parent link="world"/>
    <child link="xMatePro7_base"/>
  </joint>
  <!--base-->
  <link name="xMatePro7_base">
    <visual>
      <geometry>
        <mesh filename="package://rokae_description/meshes/visual/xMatePro7_base.stl" scale="0.001 0.001 0.001"/>
      </geometry>
      <origin rpy="0 0 0" xyz="0.0 0.0 0.0"/>
      <material name="white"/>
    </visual>
    <inertial>
      <mass value="5.48267"/>
      <inertia
        ixx="0.011844482554324"
        ixy="-0.00194355041177005"
        ixz="-2.92405347400851E-05"
        iyy="0.0135747664674373"
        iyz="-5.2965948404445E-06"
        izz="0.0164852496556854" />
      <origin rpy="0 0 0" xyz="-0.0183 0 0.067"/>
    </inertial>
    <collision>
      <geometry>
        <mesh filename="package://rokae_description/meshes/collision/xMatePro7_base.stl" scale="0.001 0.001 0.001"/>
      </geometry>
      <origin rpy="0 0 0" xyz="0.0 0.0 0.0"/>
    </collision>
  </link>
  <joint name="xmate_joint_1" type="revolute">
    <parent link="xMatePro7_base"/>
    <child link="xMatePro7_link1"/>
    <!-- 2.8449 -->
    <limit effort="300" lower="-3.1415" upper="3.1415" velocity="2.00001"/>
    <axis xyz="0 0 1"/>
    <origin rpy="0 0 0" xyz="0 0 0"/>
  </joint>
  <transmission name="tran1">
    <type>transmission_interface/SimpleTransmission</type>
    <joint name="xmate_joint_1">
      <hardwareInterface>EffortJointInterface</hardwareInterface>
    </joint>
    <actuator name="motor1">
      <hardwareInterface>EffortJointInterface</hardwareInterface>
      <mechanicalReduction>1</mechanicalReduction>
    </actuator>
  </transmission>
  <!--link 1-->
  <link name="xMatePro7_link1">
    <visual>
      <geometry>
        <mesh filename="package://rokae_description/meshes/visual/xMatePro7_link1.stl" scale="0.001 0.001 0.001"/>
      </geometry>
      <origin rpy="0 0 0" xyz="0 0 0"/>
      <material name="white"/>
    </visual>
    <inertial>
      <mass value="5.96204"/>
      <inertia
        ixx="0.00956980817859852"
        ixy="-6.86187730848903E-07"
        ixz="-4.77939159291277E-07"
        iyy="0.0085642763971582"
        iyz="0.00195727255879792"
        izz="0.00330558169504216" />
      <origin rpy="0 0 0" xyz="0 -0.017 0.320"/>
    </inertial>
    <collision>
      <geometry>
        <mesh filename="package://rokae_description/meshes/collision/xMatePro7_link1.stl" scale="0.001 0.001 0.001"/>
      </geometry>
      <origin rpy="0 0 0" xyz="0 0 0"/>
    </collision>
  </link>
  <joint name="xmate_joint_2" type="revolute">
    <parent link="xMatePro7_link1"/>
    <child link="xMatePro7_link2"/>
    <!-- 2.007 -->
    <limit effort="300" lower="-3.1415" upper="3.1415" velocity="2.00001"/>
    <axis xyz="0 1 0"/>
    <origin rpy="0 0 0" xyz="0 0 0.404"/>
  </joint>
  <transmission name="tran2">
    <type>transmission_interface/SimpleTransmission</type>
    <joint name="xmate_joint_2">
      <hardwareInterface>EffortJointInterface</hardwareInterface>
    </joint>
    <actuator name="motor2">
      <hardwareInterface>EffortJointInterface</hardwareInterface>
      <mechanicalReduction>1</mechanicalReduction>
    </actuator>
  </transmission>
  <!--link 2-->
  <link name="xMatePro7_link2">
    <visual>
      <geometry>
        <mesh filename="package://rokae_description/meshes/visual/xMatePro7_link2.stl" scale="0.001 0.001 0.001"/>
      </geometry>
      <origin rpy="0 0 0" xyz="0 0 0.0"/>
      <material name="white"/>
    </visual>
    <inertial>
      <mass value="5.40302"/>
      <inertia
        ixx="0.0179611048384865"
        ixy="7.21437672848127E-07"
        ixz="-2.15055831293158E-07"
        iyy="0.0162948618389586"
        iyz="0.00456709931969271"
        izz="0.00446726252423913" />
      <origin rpy="0 0 0" xyz="0 0.032 0.093"/>
    </inertial>
    <collision>
      <geometry>
        <mesh filename="package://rokae_description/meshes/collision/xMatePro7_link2.stl" scale="0.001 0.001 0.001"/>
      </geometry>
      <origin rpy="0 0 0" xyz="0 0 0.0"/>
    </collision>
  </link>
  <joint name="xmate_joint_3" type="revolute">
    <parent link="xMatePro7_link2"/>
    <child link="xMatePro7_link3"/>
    <!-- 2.8449 -->
    <limit effort="300" lower="-3.1415" upper="3.1415" velocity="2.00001"/>
    <axis xyz="0 0 1"/>
    <origin rpy="0 0 0" xyz="0 0 0.23743878"/>
  </joint>
  <transmission name="tran3">
    <type>transmission_interface/SimpleTransmission</type>
    <joint name="xmate_joint_3">
      <hardwareInterface>EffortJointInterface</hardwareInterface>
    </joint>
    <actuator name="motor3">
      <hardwareInterface>EffortJointInterface</hardwareInterface>
      <mechanicalReduction>1</mechanicalReduction>
    </actuator>
  </transmission>
  <!--link 3-->
  <link name="xMatePro7_link3">
    <visual>
      <geometry>
        <mesh filename="package://rokae_description/meshes/visual/xMatePro7_link3.stl" scale="0.001 0.001 0.001"/>
      </geometry>
      <origin rpy="0 0 0" xyz="0 0 0.15549959"/>
      <material name="white"/>
    </visual>
    <inertial>
      <mass value="3.95735"/>
      <inertia
        ixx="0.00952181105837379"
        ixy="-6.22715186061636E-07"
        ixz="-6.11289904635674E-07"
        iyy="0.00854581734707774"
        iyz="0.00193686004731252"
        izz="0.00327595965031583" />
      <origin rpy="0 0 0" xyz="0 -0.013 -0.067"/>
    </inertial>
    <collision>
      <geometry>
        <mesh filename="package://rokae_description/meshes/collision/xMatePro7_link3.stl" scale="0.001 0.001 0.001"/>
      </geometry>
      <origin rpy="0 0 0" xyz="0 0 0.15549959"/>
    </collision>
  </link>
  <joint name="xmate_joint_4" type="revolute">
    <parent link="xMatePro7_link3"/>
    <child link="xMatePro7_link4"/>
    <!-- 2.007 -->
    <limit effort="300" lower="-3.1415" upper="3.1415" velocity="2.00001"/>
    <!--     lower="-2.79" upper="2.79" -->
    <axis xyz="0 1 0"/>
    <!--     <origin rpy="0 0 0" xyz="0.585 0.0 0.035"/> -->
    <origin rpy="0 0 0" xyz="0 0 0.15549959"/>
  </joint>
  <transmission name="tran4">
    <type>transmission_interface/SimpleTransmission</type>
    <joint name="xmate_joint_4">
      <hardwareInterface>EffortJointInterface</hardwareInterface>
    </joint>
    <actuator name="motor4">
      <hardwareInterface>EffortJointInterface</hardwareInterface>
      <mechanicalReduction>1</mechanicalReduction>
    </actuator>
  </transmission>
  <!--link 4-->
  <link name="xMatePro7_link4">
    <visual>
      <geometry>
        <mesh filename="package://rokae_description/meshes/visual/xMatePro7_link4.stl" scale=".001 0.001 0.001"/>
      </geometry>
      <origin rpy="0 0 0" xyz="0.0 0.0 0.0"/>
      <material name="white"/>
    </visual>
    <inertial>
      <mass value="2.91217"/>
      <inertia
        ixx="0.0130624459396221"
        ixy="1.5719897750201E-07"
        ixz="-7.33111988346988E-07"
        iyy="0.0117335231217538"
        iyz="0.00345961572274007"
        izz="0.00334823361497166" />
      <origin rpy="0 0 0" xyz="0 0.026 0.068"/>
    </inertial>
    <collision>
      <geometry>
        <mesh filename="package://rokae_description/meshes/collision/xMatePro7_link4.stl" scale="0.001 0.001 0.001"/>
      </geometry>
      <origin rpy="0 0 0" xyz="0.0 0.0 0.0"/>
    </collision>
  </link>
  <joint name="xmate_joint_5" type="revolute">
    <parent link="xMatePro7_link4"/>
    <child link="xMatePro7_link5"/>
    <!-- 2.8449 -->
    <limit effort="300" lower="-3.1415" upper="3.1415" velocity="2.00001"/>
    <axis xyz="0 0 1"/>
    <origin rpy="0 0 0" xyz="0 0 0.22044633"/>
  </joint>
  <transmission name="tran5">
    <type>transmission_interface/SimpleTransmission</type>
    <joint name="xmate_joint_5">
      <hardwareInterface>EffortJointInterface</hardwareInterface>
    </joint>
    <actuator name="motor5">
      <hardwareInterface>EffortJointInterface</hardwareInterface>
      <mechanicalReduction>1</mechanicalReduction>
    </actuator>
  </transmission>
  <!--link 5-->
  <link name="xMatePro7_link5">
    <visual>
      <geometry>
        <mesh filename="package://rokae_description/meshes/visual/xMatePro7_link5.stl" scale="0.001 0.001 0.001"/>
      </geometry>
      <origin rpy="0 0 0" xyz="0 0 0.14512568"/>
      <material name="white"/>
    </visual>
    <inertial>
      <mass value="2.47056"/>
      <inertia
        ixx="0.00598554443133603"
        ixy="-4.79416763905675E-07"
        ixz="5.48955503508942E-07"
        iyy="0.00489834395926308"
        iyz="0.00152656942938201"
        izz="0.00226750920938528" />
      <origin rpy="0 0 0" xyz="0 -0.014 -0.079"/>
    </inertial>
    <collision>
      <geometry>
        <mesh filename="package://rokae_description/meshes/collision/xMatePro7_link5.stl" scale="0.001 0.001 0.001"/>
      </geometry>
      <origin rpy="0 0 0" xyz="0 0 0.14512568"/>
    </collision>
  </link>
  <joint name="xmate_joint_6" type="revolute">
    <parent link="xMatePro7_link5"/>
    <child link="xMatePro7_link6"/>
    <!-- 2.007 -->
    <limit effort="300" lower="-3.1415" upper="3.1415" velocity="2.00001"/>
    <axis xyz="0 1 0"/>
    <origin rpy="0.0 0.0 0" xyz="0 0 0.14512568"/>
  </joint>
  <transmission name="tran6">
    <type>transmission_interface/SimpleTransmission</type>
    <joint name="xmate_joint_6">
      <hardwareInterface>EffortJointInterface</hardwareInterface>
    </joint>
    <actuator name="motor6">
      <hardwareInterface>EffortJointInterface</hardwareInterface>
      <mechanicalReduction>1</mechanicalReduction>
    </actuator>
  </transmission>
  <!--link 6-->
  <link name="xMatePro7_link6">
    <visual>
      <geometry>
        <mesh filename="package://rokae_description/meshes/visual/xMatePro7_link6.stl" scale="0.001 0.001 0.001"/>
      </geometry>
      <origin rpy="0 0 0" xyz="0.0 0.0 0.0"/>
      <material name="white"/>
    </visual>
    <inertial>
      <mass value="2.16053"/>
      <inertia
        ixx="0.00628411139001244"
        ixy="-1.05280535747881E-07"
        ixz="3.44727565138006E-07"
        iyy="0.00598580705293545"
        iyz="0.00128418641419474"
        izz="0.00146492735530281" />
      <origin rpy="0 0 0" xyz="0 0.020 0.085"/>
    </inertial>
    <collision>
      <geometry>
        <mesh filename="package://rokae_description/meshes/collision/xMatePro7_link6.stl" scale="0.001 0.001 0.001"/>
      </geometry>
      <origin rpy="0 0 0" xyz="0.0 0.0 0.0"/>
    </collision>
  </link>
  <joint name="xmate_joint_7" type="revolute">
    <parent link="xMatePro7_link6"/>
    <child link="xMatePro7_link7"/>
    <limit effort="300" lower="-6.283" upper="6.283" velocity="2.00001"/>
    <axis xyz="0 0 1"/>
    <origin rpy="0.0 0.0 0.0" xyz="0 0 0.25090877"/>
  </joint>
  <transmission name="tran7">
    <type>transmission_interface/SimpleTransmission</type>
    <joint name="xmate_joint_7">
      <hardwareInterface>EffortJointInterface</hardwareInterface>
    </joint>
    <actuator name="motor7">
      <hardwareInterface>EffortJointInterface</hardwareInterface>
      <mechanicalReduction>1</mechanicalReduction>
    </actuator>
  </transmission>
  <!--link 7-->
  <link name="xMatePro7_link7">
    <visual>
      <geometry>
        <mesh filename="package://rokae_description/meshes/visual/xMatePro7_link7.stl" scale="0.001 0.001 0.001"/>
      </geometry>
      <origin rpy="0 0 0" xyz="0 0 0"/>
      <material name="white"/>
    </visual>
    <inertial>
      <mass value="1.26834"/>
      <inertia
        ixx="0.00116639457832689"
        ixy="-2.2223708270725E-07"
        ixz="-4.20922180182255E-07"
        iyy="0.000638418120517181"
        iyz="0.000282361521466337"
        izz="0.000951964055085067" />
      <origin rpy="0 0 0" xyz="0 0.012 -0.052"/>
    </inertial>
    <collision>
      <geometry>
        <mesh filename="package://rokae_description/meshes/collision/xMatePro7_link7.stl" scale="0.001 0.001 0.001"/>
      </geometry>
      <origin rpy="0 0 0" xyz="0 0 0"/>
    </collision>
  </link>
  <!-- 导入法兰的URDF -->
  <link name="falan_link">
	<visual>
	    <geometry>
	        <cylinder radius="0.04" length="0.046"/>
	    </geometry>
      <material name="blue"/>
	</visual>
	<collision>
	    <geometry>
	        <cylinder radius="0.04" length="0.046"/>
	    </geometry>
	</collision>
   </link>

   <joint name="falan_joint" type="fixed">
	<parent link="xMatePro7_link7"/> <!-- Connect to the hand link -->
	<child link="falan_link"/>
	<origin xyz="0.0 0.0 0.025" rpy="0 0 0"/> <!-- Offset position if necessary -->
    </joint>


  <!-- 导入机械手的URDF -->

        <link name="robotiq_85_base_link">
            <visual>
                <geometry>
                    <mesh filename="package://rokae_description/meshes/visual/2f_85/robotiq_base.dae" />
                </geometry>
            </visual>
            <collision>
                <geometry>
                    <mesh filename="package://rokae_description/meshes/collision/2f_85/robotiq_base.stl" />
                </geometry>
            </collision>
            <inertial>
                <origin xyz="0.0 2.274e-05 0.03232288" rpy="0 0 0" />
                <mass value="6.6320197e-01" />
                <inertia ixx="5.1617816e-04" iyy="5.8802208e-04" izz="3.9462776e-04" ixy="2.936e-8" ixz="0.0" iyz="-3.2296e-7" />
            </inertial>
        </link>

        <link name="robotiq_85_left_knuckle_link">
            <visual>
                <geometry>
                    <mesh filename="package://rokae_description/meshes/visual/2f_85/left_knuckle.dae" />
                </geometry>
            </visual>
            <collision>
                <geometry>
                    <mesh filename="package://rokae_description/meshes/collision/2f_85/left_knuckle.stl" />
                </geometry>
            </collision>
            <inertial>
                <origin xyz="0.01213197 0.0002 -0.00058647" rpy="0 0 0" />
                <mass value="1.384773208e-02" />
                <inertia ixx="3.5232e-7" iyy="2.31944e-6" izz="2.23136e-6" ixy="0.0" ixz="1.1744e-7" iyz="0" />
            </inertial>
        </link>

        <link name="robotiq_85_right_knuckle_link">
            <visual>
                <geometry>
                    <mesh filename="package://rokae_description/meshes/visual/2f_85/right_knuckle.dae" />
                </geometry>
            </visual>
            <collision>
                <geometry>
                    <mesh filename="package://rokae_description/meshes/collision/2f_85/right_knuckle.stl" />
                </geometry>
            </collision>
            <inertial>
                <origin xyz="-0.01213197 0.0002 -0.00058647" rpy="0 0 0" />
                <mass value="1.384773208e-02" />
                <inertia ixx="3.5232e-7" iyy="2.31944e-6" izz="2.23136e-6" ixy="0.0" ixz="-1.1744e-7" iyz="0.0" />
            </inertial>
        </link>

        <link name="robotiq_85_left_finger_link">
            <visual>
                <geometry>
                    <mesh filename="package://rokae_description/meshes/visual/2f_85/left_finger.dae" />
                </geometry>
            </visual>
            <collision>
                <geometry>
                    <mesh filename="package://rokae_description/meshes/collision/2f_85/left_finger.stl" />
                </geometry>
            </collision>
            <inertial>
                <origin xyz="0.00346899 -0.00079447 0.01867121" rpy="0 0 0" />
                <mass value="4.260376752e-02" />
                <inertia ixx="1.385792000000000e-05" iyy="1.183208e-05" izz="5.19672e-06" ixy="0.0" ixz="-2.17264e-06" iyz="0.0" />
            </inertial>
        </link>

        <link name="robotiq_85_right_finger_link">
            <visual>
                <geometry>
                    <mesh filename="package://rokae_description/meshes/visual/2f_85/right_finger.dae" />
                </geometry>
            </visual>
            <collision>
                <geometry>
                    <mesh filename="package://rokae_description/meshes/collision/2f_85/right_finger.stl" />
                </geometry>
            </collision>
            <inertial>
                <origin xyz="-0.00346899 -5.53e-06 0.01867121" rpy="0 0 0" />
                <mass value="4.260376752000000e-02" />
                <inertia ixx="1.385792e-05" iyy="1.183208e-05" izz="5.19672e-06" ixy="0.0" ixz="2.17264e-06" iyz="0.0" />
            </inertial>
        </link>

        <link name="robotiq_85_left_inner_knuckle_link">
            <visual>
                <geometry>
                    <mesh filename="package://rokae_description/meshes/visual/2f_85/left_inner_knuckle.dae" />
                </geometry>
            </visual>
            <collision>
                <geometry>
                    <mesh filename="package://rokae_description/meshes/collision/2f_85/left_inner_knuckle.stl" />
                </geometry>
            </collision>
            <inertial>
                <origin xyz="0.01897699 0.00015001 0.02247101" rpy="0 0 0" />
                <mass value="2.969376448e-02" />
                <inertia ixx="9.57136e-06" iyy="8.69056e-06" izz="8.19144e-06" ixy="0.0" ixz="-3.93424e-06" iyz="0.0" />
            </inertial>
        </link>

        <link name="robotiq_85_right_inner_knuckle_link">
            <visual>
                <geometry>
                    <mesh filename="package://rokae_description/meshes/visual/2f_85/right_inner_knuckle.dae" />
                </geometry>
            </visual>
            <collision>
                <geometry>
                    <mesh filename="package://rokae_description/meshes/collision/2f_85/right_inner_knuckle.stl" />
                </geometry>
            </collision>
            <inertial>
                <origin xyz="-0.01926824 5.001e-05 0.02222178" rpy="0 0 0" />
                <mass value="2.969376448e-02" />
                <inertia ixx="9.42456e-06" iyy="8.69056e-06" izz="8.33824e-06" ixy="0.0" ixz="3.9636e-06" iyz="0.0" />
            </inertial>
        </link>

        <link name="robotiq_85_left_finger_tip_link">
            <visual>
                <geometry>
                    <mesh filename="package://rokae_description/meshes/visual/2f_85/left_finger_tip.dae" />
                </geometry>
            </visual>
            <collision>
                <geometry>
                    <mesh filename="package://rokae_description/meshes/collision/2f_85/left_finger_tip.stl" />
                </geometry>
                <surface>
                    <friction>
                    <ode>
                        <mu1>100000.0</mu1>
                        <mu2>100000.0</mu2>
                    </ode>
                    </friction>
                    <contact>
                    <ode>
                        <kp>1e+5</kp>
                        <kd>1</kd>
                        <soft_cfm>0</soft_cfm>
                        <soft_erp>0.2</soft_erp>
                        <minDepth>0.002</minDepth>
                        <maxVel>0</maxVel>
                    </ode>
                    </contact>
                </surface>
            </collision>
            <inertial>
                <origin xyz="-0.01456706 -0.0008 0.01649701" rpy="0 0 0" />
                <mass value="4.268588744e-02" />
                <inertia ixx="1.048152e-05" iyy="1.197888e-05" izz="4.22784e-06" ixy="0.0" ixz="3.5232e-6" iyz="0.0" />
            </inertial>
        </link>

        <link name="robotiq_85_right_finger_tip_link">
            <visual>
                <geometry>
                    <mesh filename="package://rokae_description/meshes/visual/2f_85/right_finger_tip.dae" />
                </geometry>
            </visual>
            <collision>
                <geometry>
                    <mesh filename="package://rokae_description/meshes/collision/2f_85/right_finger_tip.stl" />
                </geometry>
                <surface>
                    <friction>
                    <ode>
                        <mu1>100000.0</mu1>
                        <mu2>100000.0</mu2>
                    </ode>
                    </friction>
                    <contact>
                    <ode>
                        <kp>1e+5</kp>
                        <kd>1</kd>
                        <soft_cfm>0</soft_cfm>
                        <soft_erp>0.2</soft_erp>
                        <minDepth>0.002</minDepth>
                        <maxVel>0</maxVel>
                    </ode>
                    </contact>
                </surface>
            </collision>
            <inertial>
                <origin xyz="0.01456706 5e-05 0.01649701" rpy="0 0 0" />
                <mass value="4.268588744e-02" />
                <inertia ixx="1.048152e-05" iyy="1.197888e-05" izz="4.22784e-06" ixy="0.0" ixz="-3.5232e-06" iyz="0.0" />
            </inertial>
        </link>

        <link name= "block_link">
        </link>

        <joint name="robotiq_85_base_joint" type="fixed">
            <parent link="falan_link" />
            <child link="robotiq_85_base_link" />
            <origin xyz="0.0 0 0.025" rpy="0 0 0.7854" />
        </joint>

        <joint name="robotiq_85_left_knuckle_joint" type="revolute">
            <parent link="robotiq_85_base_link" />
            <child link="robotiq_85_left_knuckle_link" />
            <axis xyz="0 -1 0" />
            <origin xyz="0.03060114 0.0 0.05490452" rpy="0 0 0" />
            <limit lower="0.0" upper="0.8" velocity="0.5" effort="50" />
        </joint>

        <joint name="robotiq_85_right_knuckle_joint" type="revolute">
            <parent link="robotiq_85_base_link" />
            <child link="robotiq_85_right_knuckle_link" />
            <axis xyz="0 -1 0" />
            <origin xyz="-0.03060114 0.0 0.05490452" rpy="0 0 0" />
            <limit lower="-0.8" upper="0.0" velocity="0.5" effort="50" />
            <mimic joint="robotiq_85_left_knuckle_joint" multiplier="-1" />
        </joint>

        <joint name="robotiq_85_left_finger_joint" type="fixed">
            <parent link="robotiq_85_left_knuckle_link" />
            <child link="robotiq_85_left_finger_link" />
            <origin xyz="0.03152616 0.0 -0.00376347" rpy="0 0 0" />
        </joint>

        <joint name="robotiq_85_right_finger_joint" type="fixed">
            <parent link="robotiq_85_right_knuckle_link" />
            <child link="robotiq_85_right_finger_link" />
            <origin xyz="-0.03152616 0.0 -0.00376347" rpy="0 0 0" />
        </joint>

        <joint name="robotiq_85_left_inner_knuckle_joint" type="continuous">
            <parent link="robotiq_85_base_link" />
            <child link="robotiq_85_left_inner_knuckle_link" />
            <axis xyz="0 -1 0" />
            <origin xyz="0.0127 0.0 0.06142" rpy="0 0 0" />
            <mimic joint="robotiq_85_left_knuckle_joint" />
        </joint>

        <joint name="robotiq_85_right_inner_knuckle_joint" type="continuous">
            <parent link="robotiq_85_base_link" />
            <child link="robotiq_85_right_inner_knuckle_link" />
            <axis xyz="0 -1 0" />
            <origin xyz="-0.0127 0.0 0.06142" rpy="0 0 0" />
            <mimic joint="robotiq_85_left_knuckle_joint" multiplier="-1" />
        </joint>

        <joint name="robotiq_85_left_finger_tip_joint" type="continuous">
            <parent link="robotiq_85_left_finger_link" />
            <child link="robotiq_85_left_finger_tip_link" />
            <axis xyz="0 -1 0" />
            <origin xyz="0.00563134 0.0 0.04718515" rpy="0 0 0" />
            <mimic joint="robotiq_85_left_knuckle_joint" multiplier="-1" />
        </joint>

        <joint name="robotiq_85_right_finger_tip_joint" type="continuous">
            <parent link="robotiq_85_right_finger_link" />
            <child link="robotiq_85_right_finger_tip_link" />
            <axis xyz="0 -1 0" />
            <origin xyz="-0.00563134 0.0 0.04718515" rpy="0 0 0" />
            <mimic joint="robotiq_85_right_knuckle_joint" multiplier="-1" />
        </joint>

        <joint name="block_joint" type="fixed">
          <parent link="falan_link"/>
          <child link="block_link"/>
          <origin xyz="0.0 0 0.175" rpy="0 0 0.7854" />
        </joint>

  <!-- 定义机械臂和机械手之间的连接点 -->
</robot>

